<mujoco model="g1_d_wheeled_proxy">
  <!--
    G1-D Wheeled Proxy
    Beine ersetzt durch quaderförmigen Fahrwerk-Sockel + 4 Räder (statisch).
    Torso, Arme und Aktuatoren identisch zu g1_29dof.xml.
    Pelvis-Position: Z=0.95 (Sockel 0.4m hoch, Pelvis sitzt 0.55m darüber).
  -->
  <compiler angle="radian" meshdir="meshes" />

  <default>
    <default class="torso_motor">
      <joint damping="0.05" armature="0.01" frictionloss="0.2"/>
    </default>
    <default class="arm_motor">
      <joint damping="0.05" armature="0.01" frictionloss="0.2"/>
    </default>
    <default class="wrist_motor">
      <joint damping="0.05" armature="0.01" frictionloss="0.1"/>
    </default>
  </default>

  <asset>
    <mesh name="torso_link"               file="torso_link.STL" />
    <mesh name="logo_link"                file="logo_link.STL" />
    <mesh name="head_link"                file="head_link.STL" />
    <mesh name="waist_support_link"       file="waist_support_link.STL" />
    <mesh name="waist_yaw_link"           file="waist_yaw_link.STL" />
    <mesh name="waist_roll_link"          file="waist_roll_link.STL" />
    <mesh name="left_shoulder_pitch_link" file="left_shoulder_pitch_link.STL" />
    <mesh name="left_shoulder_roll_link"  file="left_shoulder_roll_link.STL" />
    <mesh name="left_shoulder_yaw_link"   file="left_shoulder_yaw_link.STL" />
    <mesh name="left_elbow_link"          file="left_elbow_link.STL" />
    <mesh name="left_wrist_roll_link"     file="left_wrist_roll_link.STL" />
    <mesh name="left_wrist_pitch_link"    file="left_wrist_pitch_link.STL" />
    <mesh name="left_wrist_yaw_link"      file="left_wrist_yaw_link.STL" />
    <mesh name="left_rubber_hand"         file="left_rubber_hand.STL" />
    <mesh name="right_shoulder_pitch_link" file="right_shoulder_pitch_link.STL" />
    <mesh name="right_shoulder_roll_link"  file="right_shoulder_roll_link.STL" />
    <mesh name="right_shoulder_yaw_link"   file="right_shoulder_yaw_link.STL" />
    <mesh name="right_elbow_link"          file="right_elbow_link.STL" />
    <mesh name="right_wrist_roll_link"     file="right_wrist_roll_link.STL" />
    <mesh name="right_wrist_pitch_link"    file="right_wrist_pitch_link.STL" />
    <mesh name="right_wrist_yaw_link"      file="right_wrist_yaw_link.STL" />
    <mesh name="right_rubber_hand"         file="right_rubber_hand.STL" />
  </asset>

  <worldbody>
    <!--
      Pelvis = Verbindungspunkt Sockel ↔ Torso.
      pos Z=0.95: Sockel (Höhe 0.4m, Halbhöhe 0.2m) → Oberkante bei 0.4m,
      Pelvis 0.55m über Sockel-Oberkante = 0.95m über Boden.
    -->
    <body name="pelvis" pos="0 0 0.95">
      <site name="imu" size="0.01" pos="0.0 0.0 0.0" />
      <inertial pos="0 0 -0.07605" quat="1 0 -0.000399148 0" mass="3.813"
        diaginertia="0.010549 0.0093089 0.0079184" />
      <joint name="floating_base_joint" type="free" limited="false" actuatorfrclimited="false" />

      <!-- ── Quaderförmiger Fahrwerk-Sockel (ersetzt Beine) ── -->
      <geom name="chassis_box"
            type="box" size="0.15 0.10 0.20"
            pos="0 0 -0.55"
            rgba="0.15 0.15 0.15 1"
            mass="15.0"/>
      <!-- 4 Räder (statisch, kugelförmig) -->
      <geom name="wheel_fl" type="sphere" size="0.07"
            pos=" 0.12  0.12 -0.73" rgba="0.1 0.1 0.1 1" mass="0.8"/>
      <geom name="wheel_fr" type="sphere" size="0.07"
            pos=" 0.12 -0.12 -0.73" rgba="0.1 0.1 0.1 1" mass="0.8"/>
      <geom name="wheel_rl" type="sphere" size="0.07"
            pos="-0.12  0.12 -0.73" rgba="0.1 0.1 0.1 1" mass="0.8"/>
      <geom name="wheel_rr" type="sphere" size="0.07"
            pos="-0.12 -0.12 -0.73" rgba="0.1 0.1 0.1 1" mass="0.8"/>

      <!-- ── Torso (identisch g1_29dof) ── -->
      <body name="waist_yaw_link">
        <inertial pos="0.003964 0 0.018769" quat="-0.0178291 0.628464 0.0282471 0.777121"
          mass="0.244" diaginertia="0.000158561 0.000124229 9.67669e-05" />
        <joint name="waist_yaw_joint" pos="0 0 0" axis="0 0 1" range="-2.618 2.618"
          actuatorfrcrange="-88 88" class="torso_motor"/>
        <geom type="mesh" contype="0" conaffinity="0" group="1" density="0" rgba="0.7 0.7 0.7 1"
          mesh="waist_yaw_link" />
        <body name="waist_roll_link" pos="-0.0039635 0 0.035">
          <inertial pos="0 -0.000236 0.010111" quat="0.99979 0.020492 0 0" mass="0.047"
            diaginertia="7.515e-06 6.40206e-06 3.98394e-06" />
          <joint name="waist_roll_joint" pos="0 0 0" axis="1 0 0" range="-0.52 0.52"
            actuatorfrcrange="-50 50" class="torso_motor"/>
          <geom type="mesh" contype="0" conaffinity="0" group="1" density="0" rgba="0.7 0.7 0.7 1"
            mesh="waist_roll_link" />
          <site name="secondary_imu" size="0.01" pos="-0.03959 -0.00224 0.13792"/>
          <body name="torso_link" pos="0 0 0.019">
            <inertial pos="0.00331658 0.000261533 0.179856"
              quat="0.999831 0.000376204 0.0179895 -0.00377704" mass="9.598"
              diaginertia="0.12407 0.111951 0.0325382" />
            <joint name="waist_pitch_joint" pos="0 0 0" axis="0 1 0" range="-0.52 0.52"
              actuatorfrcrange="-50 50" class="torso_motor"/>
            <geom type="mesh" contype="0" conaffinity="0" group="1" density="0" rgba="0.7 0.7 0.7 1"
              mesh="torso_link" />
            <geom type="mesh" rgba="0.7 0.7 0.7 1" mesh="torso_link" />
            <geom pos="0.0039635 0 -0.054" quat="1 0 0 0" type="mesh" contype="0" conaffinity="0"
              group="1" density="0" rgba="0.2 0.2 0.2 1" mesh="logo_link" />
            <geom pos="0.0039635 0 -0.054" quat="1 0 0 0" type="mesh" rgba="0.2 0.2 0.2 1"
              mesh="logo_link" />
            <geom pos="0.0039635 0 -0.054" type="mesh" contype="0" conaffinity="0" group="1"
              density="0" rgba="0.2 0.2 0.2 1" mesh="head_link" />
            <geom pos="0.0039635 0 -0.054" type="mesh" rgba="0.2 0.2 0.2 1" mesh="head_link" />
            <geom pos="0.0039635 0 -0.054" quat="1 0 0 0" type="mesh" contype="0" conaffinity="0"
              group="1" density="0" rgba="0.7 0.7 0.7 1" mesh="waist_support_link" />
            <geom pos="0.0039635 0 -0.054" quat="1 0 0 0" type="mesh" rgba="0.7 0.7 0.7 1"
              mesh="waist_support_link" />

            <!-- ── Linker Arm ── -->
            <body name="left_shoulder_pitch_link" pos="0.0039563 0.10022 0.23778"
              quat="0.990264 0.139201 1.38722e-05 -9.86868e-05">
              <inertial pos="0 0.035892 -0.011628" quat="0.654152 0.0130458 -0.326267 0.68225"
                mass="0.718" diaginertia="0.000465864 0.000432842 0.000406394" />
              <joint name="left_shoulder_pitch_joint" pos="0 0 0" axis="0 1 0"
                range="-3.0892 2.6704" actuatorfrcrange="-25 25" class="arm_motor" />
              <geom type="mesh" contype="0" conaffinity="0" group="1" density="0"
                rgba="0.7 0.7 0.7 1" mesh="left_shoulder_pitch_link" />
              <geom size="0.03 0.025" pos="0 0.04 -0.01" quat="0.707107 0 0.707107 0"
                type="cylinder" rgba="0.7 0.7 0.7 1" />
              <body name="left_shoulder_roll_link" pos="0 0.038 -0.013831"
                quat="0.990268 -0.139172 0 0">
                <inertial pos="-0.000227 0.00727 -0.063243"
                  quat="0.701256 -0.0196223 -0.00710317 0.712604" mass="0.643"
                  diaginertia="0.000691311 0.000618011 0.000388977" />
                <joint name="left_shoulder_roll_joint" pos="0 0 0" axis="1 0 0"
                  range="-1.5882 2.2515" actuatorfrcrange="-25 25" class="arm_motor" />
                <geom type="mesh" contype="0" conaffinity="0" group="1" density="0"
                  rgba="0.7 0.7 0.7 1" mesh="left_shoulder_roll_link" />
                <geom size="0.03 0.015" pos="-0.004 0.006 -0.053" type="cylinder"
                  rgba="0.7 0.7 0.7 1" />
                <body name="left_shoulder_yaw_link" pos="0 0.00624 -0.1032">
                  <inertial pos="0.010773 -0.002949 -0.072009"
                    quat="0.716879 -0.0964829 -0.0679942 0.687134" mass="0.734"
                    diaginertia="0.00106187 0.00103217 0.000400661" />
                  <joint name="left_shoulder_yaw_joint" pos="0 0 0" axis="0 0 1"
                    range="-2.618 2.618" actuatorfrcrange="-25 25" class="arm_motor" />
                  <geom type="mesh" contype="0" conaffinity="0" group="1" density="0"
                    rgba="0.7 0.7 0.7 1" mesh="left_shoulder_yaw_link" />
                  <geom type="mesh" rgba="0.7 0.7 0.7 1" mesh="left_shoulder_yaw_link" />
                  <body name="left_elbow_link" pos="0.015783 0 -0.080518">
                    <inertial pos="0.064956 0.004454 -0.010062"
                      quat="0.541765 0.636132 0.388821 0.388129" mass="0.6"
                      diaginertia="0.000443035 0.000421612 0.000259353" />
                    <joint name="left_elbow_joint" pos="0 0 0" axis="0 1 0" range="-1.0472 2.0944"
                      actuatorfrcrange="-25 25" class="arm_motor" />
                    <geom type="mesh" contype="0" conaffinity="0" group="1" density="0"
                      rgba="0.7 0.7 0.7 1" mesh="left_elbow_link" />
                    <geom type="mesh" rgba="0.7 0.7 0.7 1" mesh="left_elbow_link" />
                    <body name="left_wrist_roll_link" pos="0.1 0.00188791 -0.01">
                      <inertial pos="0.0171394 0.000537591 4.8864e-07"
                        quat="0.575338 0.411667 -0.574906 0.411094" mass="0.085445"
                        diaginertia="5.48211e-05 4.96646e-05 3.57798e-05" />
                      <joint name="left_wrist_roll_joint" pos="0 0 0" axis="1 0 0"
                        range="-1.97222 1.97222" actuatorfrcrange="-25 25" class="arm_motor" />
                      <geom type="mesh" contype="0" conaffinity="0" group="1" density="0"
                        rgba="0.7 0.7 0.7 1" mesh="left_wrist_roll_link" />
                      <geom type="mesh" rgba="0.7 0.7 0.7 1" mesh="left_wrist_roll_link" />
                      <body name="left_wrist_pitch_link" pos="0.038 0 0">
                        <inertial pos="0.0229999 -0.00111685 -0.00111658"
                          quat="0.249998 0.661363 0.293036 0.643608" mass="0.48405"
                          diaginertia="0.000430353 0.000429873 0.000164648" />
                        <joint name="left_wrist_pitch_joint" pos="0 0 0" axis="0 1 0"
                          range="-1.61443 1.61443" actuatorfrcrange="-5 5" class="wrist_motor" />
                        <geom type="mesh" contype="0" conaffinity="0" group="1" density="0"
                          rgba="0.7 0.7 0.7 1" mesh="left_wrist_pitch_link" />
                        <geom type="mesh" rgba="0.7 0.7 0.7 1" mesh="left_wrist_pitch_link" />
                        <body name="left_wrist_yaw_link" pos="0.046 0 0">
                          <inertial pos="0.0708244 0.000191745 0.00161742"
                            quat="0.510571 0.526295 0.468078 0.493188" mass="0.254576"
                            diaginertia="0.000646113 0.000559993 0.000147566" />
                          <joint name="left_wrist_yaw_joint" pos="0 0 0" axis="0 0 1"
                            range="-1.61443 1.61443" actuatorfrcrange="-5 5" class="wrist_motor" />
                          <geom type="mesh" contype="0" conaffinity="0" group="1" density="0"
                            rgba="0.7 0.7 0.7 1" mesh="left_wrist_yaw_link" />
                          <geom type="mesh" rgba="0.7 0.7 0.7 1" mesh="left_wrist_yaw_link" />
                          <geom pos="0.0415 0.003 0" quat="1 0 0 0" type="mesh" contype="0"
                            conaffinity="0" group="1" density="0" rgba="0.7 0.7 0.7 1"
                            mesh="left_rubber_hand" />
                        </body>
                      </body>
                    </body>
                  </body>
                </body>
              </body>
            </body>

            <!-- ── Rechter Arm ── -->
            <body name="right_shoulder_pitch_link" pos="0.0039563 -0.10021 0.23778"
              quat="0.990264 -0.139201 1.38722e-05 9.86868e-05">
              <inertial pos="0 -0.035892 -0.011628" quat="0.68225 -0.326267 0.0130458 0.654152"
                mass="0.718" diaginertia="0.000465864 0.000432842 0.000406394" />
              <joint name="right_shoulder_pitch_joint" pos="0 0 0" axis="0 1 0"
                range="-3.0892 2.6704" actuatorfrcrange="-25 25" class="arm_motor" />
              <geom type="mesh" contype="0" conaffinity="0" group="1" density="0"
                rgba="0.7 0.7 0.7 1" mesh="right_shoulder_pitch_link" />
              <geom size="0.03 0.025" pos="0 -0.04 -0.01" quat="0.707107 0 0.707107 0"
                type="cylinder" rgba="0.7 0.7 0.7 1" />
              <body name="right_shoulder_roll_link" pos="0 -0.038 -0.013831"
                quat="0.990268 0.139172 0 0">
                <inertial pos="-0.000227 -0.00727 -0.063243"
                  quat="0.712604 -0.00710317 -0.0196223 0.701256" mass="0.643"
                  diaginertia="0.000691311 0.000618011 0.000388977" />
                <joint name="right_shoulder_roll_joint" pos="0 0 0" axis="1 0 0"
                  range="-2.2515 1.5882" actuatorfrcrange="-25 25" class="arm_motor" />
                <geom type="mesh" contype="0" conaffinity="0" group="1" density="0"
                  rgba="0.7 0.7 0.7 1" mesh="right_shoulder_roll_link" />
                <geom size="0.03 0.015" pos="-0.004 -0.006 -0.053" type="cylinder"
                  rgba="0.7 0.7 0.7 1" />
                <body name="right_shoulder_yaw_link" pos="0 -0.00624 -0.1032">
                  <inertial pos="0.010773 0.002949 -0.072009"
                    quat="0.687134 -0.0679942 -0.0964829 0.716879" mass="0.734"
                    diaginertia="0.00106187 0.00103217 0.000400661" />
                  <joint name="right_shoulder_yaw_joint" pos="0 0 0" axis="0 0 1"
                    range="-2.618 2.618" actuatorfrcrange="-25 25" class="arm_motor" />
                  <geom type="mesh" contype="0" conaffinity="0" group="1" density="0"
                    rgba="0.7 0.7 0.7 1" mesh="right_shoulder_yaw_link" />
                  <geom type="mesh" rgba="0.7 0.7 0.7 1" mesh="right_shoulder_yaw_link" />
                  <body name="right_elbow_link" pos="0.015783 0 -0.080518">
                    <inertial pos="0.064956 -0.004454 -0.010062"
                      quat="0.388129 0.388821 0.636132 0.541765" mass="0.6"
                      diaginertia="0.000443035 0.000421612 0.000259353" />
                    <joint name="right_elbow_joint" pos="0 0 0" axis="0 1 0" range="-1.0472 2.0944"
                      actuatorfrcrange="-25 25" class="arm_motor" />
                    <geom type="mesh" contype="0" conaffinity="0" group="1" density="0"
                      rgba="0.7 0.7 0.7 1" mesh="right_elbow_link" />
                    <geom type="mesh" rgba="0.7 0.7 0.7 1" mesh="right_elbow_link" />
                    <body name="right_wrist_roll_link" pos="0.1 -0.00188791 -0.01">
                      <inertial pos="0.0171394 -0.000537591 4.8864e-07"
                        quat="0.411667 0.575338 -0.411094 0.574906" mass="0.085445"
                        diaginertia="5.48211e-05 4.96646e-05 3.57798e-05" />
                      <joint name="right_wrist_roll_joint" pos="0 0 0" axis="1 0 0"
                        range="-1.97222 1.97222" actuatorfrcrange="-25 25" class="arm_motor" />
                      <geom type="mesh" contype="0" conaffinity="0" group="1" density="0"
                        rgba="0.7 0.7 0.7 1" mesh="right_wrist_roll_link" />
                      <geom type="mesh" rgba="0.7 0.7 0.7 1" mesh="right_wrist_roll_link" />
                      <body name="right_wrist_pitch_link" pos="0.038 0 0">
                        <inertial pos="0.0229999 0.00111685 -0.00111658"
                          quat="0.643608 0.293036 0.661363 0.249998" mass="0.48405"
                          diaginertia="0.000430353 0.000429873 0.000164648" />
                        <joint name="right_wrist_pitch_joint" pos="0 0 0" axis="0 1 0"
                          range="-1.61443 1.61443" actuatorfrcrange="-5 5" class="wrist_motor" />
                        <geom type="mesh" contype="0" conaffinity="0" group="1" density="0"
                          rgba="0.7 0.7 0.7 1" mesh="right_wrist_pitch_link" />
                        <geom type="mesh" rgba="0.7 0.7 0.7 1" mesh="right_wrist_pitch_link" />
                        <body name="right_wrist_yaw_link" pos="0.046 0 0">
                          <inertial pos="0.0708244 -0.000191745 0.00161742"
                            quat="0.493188 0.468078 0.526295 0.510571" mass="0.254576"
                            diaginertia="0.000646113 0.000559993 0.000147566" />
                          <joint name="right_wrist_yaw_joint" pos="0 0 0" axis="0 0 1"
                            range="-1.61443 1.61443" actuatorfrcrange="-5 5" class="wrist_motor" />
                          <geom type="mesh" contype="0" conaffinity="0" group="1" density="0"
                            rgba="0.7 0.7 0.7 1" mesh="right_wrist_yaw_link" />
                          <geom type="mesh" rgba="0.7 0.7 0.7 1" mesh="right_wrist_yaw_link" />
                          <geom pos="0.0415 -0.003 0" quat="1 0 0 0" type="mesh" contype="0"
                            conaffinity="0" group="1" density="0" rgba="0.7 0.7 0.7 1"
                            mesh="right_rubber_hand" />
                        </body>
                      </body>
                    </body>
                  </body>
                </body>
              </body>
            </body>

          </body>
        </body>
      </body>
    </body>
  </worldbody>

  <actuator>
    <motor name="waist_yaw"   joint="waist_yaw_joint"   ctrlrange="-88 88" />
    <motor name="waist_roll"  joint="waist_roll_joint"  ctrlrange="-50 50" />
    <motor name="waist_pitch" joint="waist_pitch_joint" ctrlrange="-50 50" />

    <motor name="left_shoulder_pitch" joint="left_shoulder_pitch_joint" ctrlrange="-25 25" />
    <motor name="left_shoulder_roll"  joint="left_shoulder_roll_joint"  ctrlrange="-25 25" />
    <motor name="left_shoulder_yaw"   joint="left_shoulder_yaw_joint"   ctrlrange="-25 25" />
    <motor name="left_elbow"          joint="left_elbow_joint"          ctrlrange="-25 25" />
    <motor name="left_wrist_roll"     joint="left_wrist_roll_joint"     ctrlrange="-25 25" />
    <motor name="left_wrist_pitch"    joint="left_wrist_pitch_joint"    ctrlrange="-5 5" />
    <motor name="left_wrist_yaw"      joint="left_wrist_yaw_joint"      ctrlrange="-5 5" />

    <motor name="right_shoulder_pitch" joint="right_shoulder_pitch_joint" ctrlrange="-25 25" />
    <motor name="right_shoulder_roll"  joint="right_shoulder_roll_joint"  ctrlrange="-25 25" />
    <motor name="right_shoulder_yaw"   joint="right_shoulder_yaw_joint"   ctrlrange="-25 25" />
    <motor name="right_elbow"          joint="right_elbow_joint"          ctrlrange="-25 25" />
    <motor name="right_wrist_roll"     joint="right_wrist_roll_joint"     ctrlrange="-25 25" />
    <motor name="right_wrist_pitch"    joint="right_wrist_pitch_joint"    ctrlrange="-5 5" />
    <motor name="right_wrist_yaw"      joint="right_wrist_yaw_joint"     ctrlrange="-5 5" />
  </actuator>

  <sensor>
    <framequat name="imu_quat"  objtype="site" objname="imu" />
    <gyro      name="imu_gyro"  site="imu" />
    <accelerometer name="imu_acc" site="imu" />
    <framepos  name="frame_pos" objtype="site" objname="imu" />
    <framelinvel name="frame_vel" objtype="site" objname="imu" />
    <framequat name="secondary_imu_quat" objtype="site" objname="secondary_imu" />
    <gyro      name="secondary_imu_gyro" site="secondary_imu" noise="5e-4" cutoff="34.9"/>
    <accelerometer name="secondary_imu_acc" site="secondary_imu" noise="1e-2" cutoff="157"/>
  </sensor>

</mujoco>
